2025-01-14 22:29:51,038 - ERROR - Error: 'id'. Det oppstod en feil ved henting av DNS
2025-01-14 22:30:27,237 - ERROR - Result update - cannot access local variable 'raceclass' where it is not associated with a value
2025-01-14 22:33:30,423 - ERROR - Result update - cannot access local variable 'raceclass' where it is not associated with a value
2025-04-16 16:26:57,901 - ERROR - Error 500 getting events: <ClientResponse(http://localhost:8082/events) [500 Internal Server Error]>
<CIMultiDictProxy('Content-Type': 'application/json; charset=utf-8', 'Content-Length': '145', 'Date': 'Wed, 16 Apr 2025 14:26:57 GMT', 'Server': 'Python/3.13 aiohttp/3.11.12')>
 
2025-04-16 18:38:30,837 - ERROR - Error. Redirect to main page.
Traceback (most recent call last):
  File "/home/heming/github/result-service-gui/.venv/lib/python3.12/site-packages/aiohttp/connector.py", line 1115, in _wrap_create_connection
    sock = await aiohappyeyeballs.start_connection(
           ^^^^^^^^^^^^^^^^^^^^^^^^^^^^^^^^^^^^^^^^
  File "/home/heming/github/result-service-gui/.venv/lib/python3.12/site-packages/aiohappyeyeballs/impl.py", line 122, in start_connection
    raise first_exception
  File "/home/heming/github/result-service-gui/.venv/lib/python3.12/site-packages/aiohappyeyeballs/impl.py", line 73, in start_connection
    sock = await _connect_sock(
           ^^^^^^^^^^^^^^^^^^^^
  File "/home/heming/github/result-service-gui/.venv/lib/python3.12/site-packages/aiohappyeyeballs/impl.py", line 208, in _connect_sock
    await loop.sock_connect(sock, address)
  File "/usr/lib/python3.12/asyncio/selector_events.py", line 651, in sock_connect
    return await fut
           ^^^^^^^^^
  File "/usr/lib/python3.12/asyncio/selector_events.py", line 691, in _sock_connect_cb
    raise OSError(err, f'Connect call failed {address}')
ConnectionRefusedError: [Errno 111] Connect call failed ('127.0.0.1', 8092)

The above exception was the direct cause of the following exception:

Traceback (most recent call last):
  File "/home/heming/github/result-service-gui/result_service_gui/views/resultat_edit_new.py", line 102, in get
    foto = await PhotosAdapter().get_photos_by_race_id(
           ^^^^^^^^^^^^^^^^^^^^^^^^^^^^^^^^^^^^^^^^^^^^
  File "/home/heming/github/result-service-gui/result_service_gui/services/photos_adapter.py", line 97, in get_photos_by_race_id
    async with ClientSession() as session, session.get(
  File "/home/heming/github/result-service-gui/.venv/lib/python3.12/site-packages/aiohttp/client.py", line 1425, in __aenter__
    self._resp: _RetType = await self._coro
                           ^^^^^^^^^^^^^^^^
  File "/home/heming/github/result-service-gui/.venv/lib/python3.12/site-packages/aiohttp/client.py", line 703, in _request
    conn = await self._connector.connect(
           ^^^^^^^^^^^^^^^^^^^^^^^^^^^^^^
  File "/home/heming/github/result-service-gui/.venv/lib/python3.12/site-packages/aiohttp/connector.py", line 548, in connect
    proto = await self._create_connection(req, traces, timeout)
            ^^^^^^^^^^^^^^^^^^^^^^^^^^^^^^^^^^^^^^^^^^^^^^^^^^^
  File "/home/heming/github/result-service-gui/.venv/lib/python3.12/site-packages/aiohttp/connector.py", line 1056, in _create_connection
    _, proto = await self._create_direct_connection(req, traces, timeout)
               ^^^^^^^^^^^^^^^^^^^^^^^^^^^^^^^^^^^^^^^^^^^^^^^^^^^^^^^^^^
  File "/home/heming/github/result-service-gui/.venv/lib/python3.12/site-packages/aiohttp/connector.py", line 1400, in _create_direct_connection
    raise last_exc
  File "/home/heming/github/result-service-gui/.venv/lib/python3.12/site-packages/aiohttp/connector.py", line 1369, in _create_direct_connection
    transp, proto = await self._wrap_create_connection(
                    ^^^^^^^^^^^^^^^^^^^^^^^^^^^^^^^^^^^
  File "/home/heming/github/result-service-gui/.venv/lib/python3.12/site-packages/aiohttp/connector.py", line 1130, in _wrap_create_connection
    raise client_error(req.connection_key, exc) from exc
aiohttp.client_exceptions.ClientConnectorError: Cannot connect to host localhost:8092 ssl:default [Connect call failed ('127.0.0.1', 8092)]
2025-04-16 18:40:06,905 - ERROR - get_config failed - 500 - Config with key INTEGRATION_SERVICE_AVAILABLE not found on event cfd95a27-9805-43be-840e-9439b62b2a09
2025-04-16 18:40:06,905 - ERROR - Error. Redirect to main page.
Traceback (most recent call last):
  File "/home/heming/github/result-service-gui/result_service_gui/views/timing_dash.py", line 55, in get
    "service_status": await get_service_status(user["token"], event_id),
                      ^^^^^^^^^^^^^^^^^^^^^^^^^^^^^^^^^^^^^^^^^^^^^^^^^
  File "/home/heming/github/result-service-gui/result_service_gui/views/timing_dash.py", line 66, in get_service_status
    integration_available = await ConfigAdapter().get_config(
                            ^^^^^^^^^^^^^^^^^^^^^^^^^^^^^^^^^
  File "/home/heming/github/result-service-gui/result_service_gui/services/config_adapter.py", line 45, in get_config
    raise web.HTTPBadRequest(reason=informasjon)
aiohttp.web_exceptions.HTTPBadRequest: get_config failed - 500 - Config with key INTEGRATION_SERVICE_AVAILABLE not found on event cfd95a27-9805-43be-840e-9439b62b2a09
2025-04-16 22:39:07,441 - ERROR - Result update
Traceback (most recent call last):
  File "/home/heming/github/result-service-gui/result_service_gui/views/resultat_update.py", line 29, in post
    informasjon = await create_event(user, form, action)
                  ^^^^^^^^^^^^^^^^^^^^^^^^^^^^^^^^^^^^^^
  File "/home/heming/github/result-service-gui/result_service_gui/views/resultat_update.py", line 98, in create_event
    new_t_e = await TimeEventsAdapter().create_time_event(
              ^^^^^^^^^^^^^^^^^^^^^^^^^^^^^^^^^^^^^^^^^^^^
  File "/home/heming/github/result-service-gui/result_service_gui/services/time_events_adapter.py", line 42, in create_time_event
    raise Exception(f"401 Unathorized - {servicename}")
Exception: 401 Unathorized - create_time_event
2025-04-16 22:39:12,050 - ERROR - Error
Traceback (most recent call last):
  File "/home/heming/github/result-service-gui/result_service_gui/services/time_events_service.py", line 176, in create_finish_time_event
    new_t_e = await TimeEventsAdapter().create_time_event(token, time_event)
              ^^^^^^^^^^^^^^^^^^^^^^^^^^^^^^^^^^^^^^^^^^^^^^^^^^^^^^^^^^^^^^
  File "/home/heming/github/result-service-gui/result_service_gui/services/time_events_adapter.py", line 42, in create_time_event
    raise Exception(f"401 Unathorized - {servicename}")
Exception: 401 Unathorized - create_time_event
2025-04-16 22:39:12,072 - ERROR - Error
Traceback (most recent call last):
  File "/home/heming/github/result-service-gui/result_service_gui/services/time_events_service.py", line 176, in create_finish_time_event
    new_t_e = await TimeEventsAdapter().create_time_event(token, time_event)
              ^^^^^^^^^^^^^^^^^^^^^^^^^^^^^^^^^^^^^^^^^^^^^^^^^^^^^^^^^^^^^^
  File "/home/heming/github/result-service-gui/result_service_gui/services/time_events_adapter.py", line 42, in create_time_event
    raise Exception(f"401 Unathorized - {servicename}")
Exception: 401 Unathorized - create_time_event
2025-04-16 22:39:12,095 - ERROR - Error
Traceback (most recent call last):
  File "/home/heming/github/result-service-gui/result_service_gui/services/time_events_service.py", line 176, in create_finish_time_event
    new_t_e = await TimeEventsAdapter().create_time_event(token, time_event)
              ^^^^^^^^^^^^^^^^^^^^^^^^^^^^^^^^^^^^^^^^^^^^^^^^^^^^^^^^^^^^^^
  File "/home/heming/github/result-service-gui/result_service_gui/services/time_events_adapter.py", line 42, in create_time_event
    raise Exception(f"401 Unathorized - {servicename}")
Exception: 401 Unathorized - create_time_event
2025-04-16 22:39:12,120 - ERROR - Error
Traceback (most recent call last):
  File "/home/heming/github/result-service-gui/result_service_gui/services/time_events_service.py", line 176, in create_finish_time_event
    new_t_e = await TimeEventsAdapter().create_time_event(token, time_event)
              ^^^^^^^^^^^^^^^^^^^^^^^^^^^^^^^^^^^^^^^^^^^^^^^^^^^^^^^^^^^^^^
  File "/home/heming/github/result-service-gui/result_service_gui/services/time_events_adapter.py", line 42, in create_time_event
    raise Exception(f"401 Unathorized - {servicename}")
Exception: 401 Unathorized - create_time_event
2025-04-16 22:39:12,146 - ERROR - Error
Traceback (most recent call last):
  File "/home/heming/github/result-service-gui/result_service_gui/services/time_events_service.py", line 176, in create_finish_time_event
    new_t_e = await TimeEventsAdapter().create_time_event(token, time_event)
              ^^^^^^^^^^^^^^^^^^^^^^^^^^^^^^^^^^^^^^^^^^^^^^^^^^^^^^^^^^^^^^
  File "/home/heming/github/result-service-gui/result_service_gui/services/time_events_adapter.py", line 42, in create_time_event
    raise Exception(f"401 Unathorized - {servicename}")
Exception: 401 Unathorized - create_time_event
2025-04-16 22:39:33,479 - ERROR - Error
Traceback (most recent call last):
  File "/home/heming/github/result-service-gui/result_service_gui/services/time_events_service.py", line 176, in create_finish_time_event
    new_t_e = await TimeEventsAdapter().create_time_event(token, time_event)
              ^^^^^^^^^^^^^^^^^^^^^^^^^^^^^^^^^^^^^^^^^^^^^^^^^^^^^^^^^^^^^^
  File "/home/heming/github/result-service-gui/result_service_gui/services/time_events_adapter.py", line 40, in create_time_event
    raise Exception(f"400 - {functional_error['detail']}")
Exception: 400 - Time-event for bib 90 and timing-point Finish already exists in race 521c5075-c404-46a1-bac5-4791e18aa0df.
2025-04-16 22:39:33,514 - ERROR - Error
Traceback (most recent call last):
  File "/home/heming/github/result-service-gui/result_service_gui/services/time_events_service.py", line 176, in create_finish_time_event
    new_t_e = await TimeEventsAdapter().create_time_event(token, time_event)
              ^^^^^^^^^^^^^^^^^^^^^^^^^^^^^^^^^^^^^^^^^^^^^^^^^^^^^^^^^^^^^^
  File "/home/heming/github/result-service-gui/result_service_gui/services/time_events_adapter.py", line 40, in create_time_event
    raise Exception(f"400 - {functional_error['detail']}")
Exception: 400 - Time-event for bib 92 and timing-point Finish already exists in race 521c5075-c404-46a1-bac5-4791e18aa0df.
2025-04-16 22:39:33,554 - ERROR - Error
Traceback (most recent call last):
  File "/home/heming/github/result-service-gui/result_service_gui/services/time_events_service.py", line 176, in create_finish_time_event
    new_t_e = await TimeEventsAdapter().create_time_event(token, time_event)
              ^^^^^^^^^^^^^^^^^^^^^^^^^^^^^^^^^^^^^^^^^^^^^^^^^^^^^^^^^^^^^^
  File "/home/heming/github/result-service-gui/result_service_gui/services/time_events_adapter.py", line 40, in create_time_event
    raise Exception(f"400 - {functional_error['detail']}")
Exception: 400 - Time-event for bib 91 and timing-point Finish already exists in race 521c5075-c404-46a1-bac5-4791e18aa0df.
2025-04-16 22:39:33,581 - ERROR - Error
Traceback (most recent call last):
  File "/home/heming/github/result-service-gui/result_service_gui/services/time_events_service.py", line 176, in create_finish_time_event
    new_t_e = await TimeEventsAdapter().create_time_event(token, time_event)
              ^^^^^^^^^^^^^^^^^^^^^^^^^^^^^^^^^^^^^^^^^^^^^^^^^^^^^^^^^^^^^^
  File "/home/heming/github/result-service-gui/result_service_gui/services/time_events_adapter.py", line 40, in create_time_event
    raise Exception(f"400 - {functional_error['detail']}")
Exception: 400 - Time-event for bib 93 and timing-point Finish already exists in race 521c5075-c404-46a1-bac5-4791e18aa0df.
2025-04-16 22:39:33,605 - ERROR - Error
Traceback (most recent call last):
  File "/home/heming/github/result-service-gui/result_service_gui/services/time_events_service.py", line 176, in create_finish_time_event
    new_t_e = await TimeEventsAdapter().create_time_event(token, time_event)
              ^^^^^^^^^^^^^^^^^^^^^^^^^^^^^^^^^^^^^^^^^^^^^^^^^^^^^^^^^^^^^^
  File "/home/heming/github/result-service-gui/result_service_gui/services/time_events_adapter.py", line 40, in create_time_event
    raise Exception(f"400 - {functional_error['detail']}")
Exception: 400 - Time-event for bib 94 and timing-point Finish already exists in race 521c5075-c404-46a1-bac5-4791e18aa0df.
2025-04-16 22:43:01,007 - ERROR - Error. Det oppstod en feil ved henting av DNS
Traceback (most recent call last):
  File "/home/heming/github/result-service-gui/result_service_gui/views/timing_info.py", line 34, in get
    response = await get_dns(user, event_id, race_order)
               ^^^^^^^^^^^^^^^^^^^^^^^^^^^^^^^^^^^^^^^^^
  File "/home/heming/github/result-service-gui/result_service_gui/views/timing_info.py", line 57, in get_dns
    user["token"], race["id"]
                   ~~~~^^^^^^
KeyError: 'id'
2025-04-16 22:43:42,705 - ERROR - get_config failed - 500 - Config with key INTEGRATION_SERVICE_AVAILABLE not found on event cfd95a27-9805-43be-840e-9439b62b2a09
2025-04-16 22:43:42,705 - ERROR - Error. Redirect to main page.
Traceback (most recent call last):
  File "/home/heming/github/result-service-gui/result_service_gui/views/timing_dash.py", line 55, in get
    "service_status": await get_service_status(user["token"], event_id),
                      ^^^^^^^^^^^^^^^^^^^^^^^^^^^^^^^^^^^^^^^^^^^^^^^^^
  File "/home/heming/github/result-service-gui/result_service_gui/views/timing_dash.py", line 66, in get_service_status
    integration_available = await ConfigAdapter().get_config(
                            ^^^^^^^^^^^^^^^^^^^^^^^^^^^^^^^^^
  File "/home/heming/github/result-service-gui/result_service_gui/services/config_adapter.py", line 45, in get_config
    raise web.HTTPBadRequest(reason=informasjon)
aiohttp.web_exceptions.HTTPBadRequest: get_config failed - 500 - Config with key INTEGRATION_SERVICE_AVAILABLE not found on event cfd95a27-9805-43be-840e-9439b62b2a09
